<mujoco model="go2">
  <!-- <compiler angle="radian" meshdir="assets" autolimits="true"/> -->
  <compiler angle="radian" meshdir="robots/its_all_a_mesh" autolimits="true"/>

  <option iterations="1" ls_iterations="5" timestep="0.002" integrator="Euler">
    <flag eulerdamp="disable"/>
  </option>

  <default>
    <default class="go2">
      <geom friction="0.6" margin="0.001" condim="1"/>
      <joint axis="0 1 0" damping="2" armature="0.01"/>
      <general forcerange="-30 30" biastype="affine" gainprm="50 0 0" biasprm="0 -50 -0.5"/>

      <default class="abduction">
        <joint axis="1 0 0" range="-1.0472 1.0472"/>
        <general ctrlrange="-0.9472 0.9472"/>
      </default>
      <default class="hip">
        <joint range="-1.5708 3.4907"/>
        <general ctrlrange="-1.4 2.5"/>
      </default>
      <default class="knee">
        <joint range="-2.7227 -0.83776"/>
        <general ctrlrange="-2.6227 -0.84776"/>
      </default>
      <default class="visual">
        <geom type="mesh" contype="0" conaffinity="0" group="2"/>
      </default>
      <default class="go2foot">
        <site group="1" pos="-0.002 0 -0.213"/>
        <geom rgba="0.231373 0.380392 0.705882 1"/>
      </default>
      
      <!-- Revised collision defaults modeled after go1 -->
      <default class="collision">
        <geom group="3" type="capsule"/>
        <default class="hip_left1">
          <geom size="0.046 0.02" pos="0 0.045 0" quat="1 1 0 0" type="cylinder"/>
        </default>
        <default class="hip_left2">
          <geom size="0.031 0.02" pos="0 0.065 0" quat="1 1 0 0" type="cylinder"/>
        </default>
        <default class="hip_left3">
          <geom size="0.046 0.02" quat="1 1 0 0" type="cylinder"/>
        </default>
        <default class="hip_right1">
          <geom size="0.046 0.02" pos="0 -0.045 0" quat="1 1 0 0" type="cylinder"/>
        </default>
        <default class="hip_right2">
          <geom size="0.031 0.02" pos="0 -0.065 0" quat="1 1 0 0" type="cylinder"/>
        </default>
        <default class="hip_right3">
          <geom size="0.046 0.02" quat="1 1 0 0" type="cylinder"/>
        </default>
        <default class="thigh1">
          <geom size="0.015" fromto="-0.02 0 0 -0.02 0 -0.16"/>
        </default>
        <default class="thigh2">
          <geom size="0.015" fromto="0 0 0 -0.02 0 -0.1"/>
        </default>
        <default class="thigh3">
          <geom size="0.015" fromto="-0.02 0 -0.16 0 0 -0.2"/>
        </default>
        <default class="calf1">
          <geom size="0.01" fromto="0 0 0 0.02 0 -0.13"/>
        </default>
        <default class="calf2">
          <geom size="0.01" fromto="0.02 0 -0.13 0 0 -0.2"/>
        </default>
        <default class="foot">
          <geom type="sphere" size="0.023" pos="0 0 -0.213" solimp="0.9 0.95 0.023" condim="3"/>
        </default>
      </default>
    </default>
  </default>

  <asset>
    <material name="metal" rgba=".9 .95 .95 1"/>
    <material name="black" rgba="0 0 0 1"/>
    <material name="white" rgba="1 1 1 1"/>
    <material name="gray" rgba="0.671705 0.692426 0.774270 1"/>

    <mesh file="base_0_go2.obj"/>
    <mesh file="base_1_go2.obj"/>
    <mesh file="base_2.obj"/>
    <mesh file="base_3.obj"/>
    <mesh file="base_4.obj"/>
    <mesh file="hip_0.obj"/>
    <mesh file="hip_1.obj"/>
    <mesh file="thigh_0.obj"/>
    <mesh file="thigh_1.obj"/>
    <mesh file="thigh_mirror_0.obj"/>
    <mesh file="thigh_mirror_1.obj"/>
    <mesh file="calf_0.obj"/>
    <mesh file="calf_1.obj"/>
    <mesh file="calf_mirror_0.obj"/>
    <mesh file="calf_mirror_1.obj"/>
    <mesh file="foot.obj"/>
  </asset>

  <worldbody>
    <body name="base" pos="0 0 0.445" euler="0 0 -0.785" childclass="go2">
      <camera name="track" pos="0.846 -1.465 0.916" xyaxes="0.866 0.500 0.000 -0.171 0.296 0.940" mode="trackcom"/>
      <inertial pos="0.021112 0 -0.005366" quat="-0.000543471 0.713435 -0.00173769 0.700719" mass="6.921"
        diaginertia="0.107027 0.0980771 0.0244531"/>
      <freejoint/>
      <!-- Add camera -->
      <camera name="realsense_cam" pos="0.2 0 0.4" euler="0 -0.9 0" fovy="60"/>

      <!-- Revised base collision geoms: two cylindrical approximations -->
      <geom class="collision" type="cylinder" quat="1 0 1 0" pos="0 -0.04 0" size="0.058 0.125"/>
      <geom class="collision" type="cylinder" quat="1 0 1 0" pos="0 0.04 0" size="0.058 0.125"/>

      <!-- Head and Lidar Collision Spheres -->
      <site name="head" pos="0.285 0 0.01" rgba="1 0 0 1" size="0.02" group="5"/>
      <geom name="head_collision" type="sphere" size="0.05 0.045" pos="0.285 0 0.01" class="collision"/>
      <geom name="lidar_collision" type="sphere" size="0.043" pos="0.293 0 -0.06" class="collision"/>
      
      <!-- Base visual meshes remain unchanged -->
      <geom mesh="base_0_go2" material="black" class="visual"/>
      <geom mesh="base_1_go2" material="black" class="visual"/>
      <geom mesh="base_2" material="black" class="visual"/>
      <geom mesh="base_3" material="white" class="visual"/>
      <geom mesh="base_4" material="gray" class="visual"/>
      <site name="imu" pos="-0.02557 0 0.04232"/>

      <!-- Left Front Leg -->
      <body name="FL_hip" pos="0.1934 0.0465 0">
        <inertial pos="-0.0054 0.00194 -0.000105" quat="0.497014 0.499245 0.505462 0.498237" mass="0.678"
          diaginertia="0.00088403 0.000596003 0.000479967"/>
        <joint name="FL_hip_joint" class="abduction"/>
        <geom mesh="hip_0" material="metal" class="visual"/>
        <geom mesh="hip_1" material="gray" class="visual"/>
        <!-- Use collision defaults for left hip -->
        <geom name="fl_hip" class="hip_left1"/>
        <body name="FL_thigh" pos="0 0.0955 0">
          <inertial pos="-0.00374 -0.0223 -0.0327" quat="0.829533 0.0847635 -0.0200632 0.551623" mass="1.152"
            diaginertia="0.00594973 0.00584149 0.000878787"/>
          <joint name="FL_thigh_joint" class="hip"/>
          <geom mesh="thigh_0" material="metal" class="visual"/>
          <geom mesh="thigh_1" material="gray" class="visual"/>
          <!-- Use three collision geoms for thigh -->
          <geom name="fl_thigh1" class="thigh1"/>
          <geom name="fl_thigh2" class="thigh2"/>
          <geom name="fl_thigh3" class="thigh3"/>
          <body name="FL_calf" pos="0 0 -0.213">
            <inertial pos="0.00629595 -0.000622121 -0.141417" quat="0.710672 0.00154099 -0.00450087 0.703508"
              mass="0.241352" diaginertia="0.0014901 0.00146356 5.31397e-05"/>
            <joint name="FL_calf_joint" class="knee"/>
            <geom mesh="calf_0" material="gray" class="visual"/>
            <geom mesh="calf_1" material="black" class="visual"/>
            <!-- Two collision geoms for calf -->
            <geom name="fl_calf1" class="calf1"/>
            <geom name="fl_calf2" class="calf2"/>
            <!-- Foot: using the revised foot collision -->
            <geom pos="0 0 -0.213" mesh="foot" class="visual" material="black"/>
            <geom name="FL" class="foot"/>
            <site name="FL_foot" class="go2foot"/>
          </body>
        </body>
      </body>

      <!-- Right Front Leg -->
      <body name="FR_hip" pos="0.1934 -0.0465 0">
        <inertial pos="-0.0054 -0.00194 -0.000105" quat="0.498237 0.505462 0.499245 0.497014" mass="0.678"
          diaginertia="0.00088403 0.000596003 0.000479967"/>
        <joint name="FR_hip_joint" class="abduction"/>
        <geom mesh="hip_0" material="metal" class="visual" quat="4.63268e-05 1 0 0"/>
        <geom mesh="hip_1" material="gray" class="visual" quat="4.63268e-05 1 0 0"/>
        <!-- Use collision default for right hip -->
        <geom name="fr_hip" class="hip_right1"/>
        <body name="FR_thigh" pos="0 -0.0955 0">
          <inertial pos="-0.00374 0.0223 -0.0327" quat="0.551623 -0.0200632 0.0847635 0.829533" mass="1.152"
            diaginertia="0.00594973 0.00584149 0.000878787"/>
          <joint name="FR_thigh_joint" class="hip"/>
          <geom mesh="thigh_mirror_0" material="metal" class="visual"/>
          <geom mesh="thigh_mirror_1" material="gray" class="visual"/>
          <!-- Three collision geoms for thigh -->
          <geom name="fr_thigh1" class="thigh1"/>
          <geom name="fr_thigh2" class="thigh2"/>
          <geom name="fr_thigh3" class="thigh3"/>
          <body name="FR_calf" pos="0 0 -0.213">
            <inertial pos="0.00629595 0.000622121 -0.141417" quat="0.703508 -0.00450087 0.00154099 0.710672"
              mass="0.241352" diaginertia="0.0014901 0.00146356 5.31397e-05"/>
            <joint name="FR_calf_joint" class="knee"/>
            <geom mesh="calf_mirror_0" material="gray" class="visual"/>
            <geom mesh="calf_mirror_1" material="black" class="visual"/>
            <!-- Two collision geoms for calf -->
            <geom name="fr_calf1" class="calf1"/>
            <geom name="fr_calf2" class="calf2"/>
            <!-- Foot collision -->
            <geom pos="0 0 -0.213" mesh="foot" class="visual" material="black"/>
            <geom name="FR" class="foot"/>
            <site name="FR_foot" class="go2foot"/>
          </body>
        </body>
      </body>

      <!-- Left Rear Leg -->
      <body name="RL_hip" pos="-0.1934 0.0465 0">
        <inertial pos="0.0054 0.00194 -0.000105" quat="0.505462 0.498237 0.497014 0.499245" mass="0.678"
          diaginertia="0.00088403 0.000596003 0.000479967"/>
        <joint name="RL_hip_joint" class="abduction"/>
        <geom mesh="hip_0" material="metal" class="visual" quat="4.63268e-05 0 1 0"/>
        <geom mesh="hip_1" material="gray" class="visual" quat="4.63268e-05 0 1 0"/>
        <!-- Use collision default for left hip (rear) -->
        <geom name="rl_hip" class="hip_left1"/>
        <body name="RL_thigh" pos="0 0.0955 0">
          <inertial pos="-0.00374 -0.0223 -0.0327" quat="0.829533 0.0847635 -0.0200632 0.551623" mass="1.152"
            diaginertia="0.00594973 0.00584149 0.000878787"/>
          <joint name="RL_thigh_joint" class="hip"/>
          <geom mesh="thigh_0" material="metal" class="visual"/>
          <geom mesh="thigh_1" material="gray" class="visual"/>
          <!-- Three collision geoms for thigh -->
          <geom name="rl_thigh1" class="thigh1"/>
          <geom name="rl_thigh2" class="thigh2"/>
          <geom name="rl_thigh3" class="thigh3"/>
          <body name="RL_calf" pos="0 0 -0.213">
            <inertial pos="0.00629595 -0.000622121 -0.141417" quat="0.710672 0.00154099 -0.00450087 0.703508"
              mass="0.241352" diaginertia="0.0014901 0.00146356 5.31397e-05"/>
            <joint name="RL_calf_joint" class="knee"/>
            <geom mesh="calf_0" material="gray" class="visual"/>
            <geom mesh="calf_1" material="black" class="visual"/>
            <!-- Two collision geoms for calf -->
            <geom name="rl_calf1" class="calf1"/>
            <geom name="rl_calf2" class="calf2"/>
            <!-- Foot collision -->
            <geom pos="0 0 -0.213" mesh="foot" class="visual" material="black"/>
            <geom name="RL" class="foot"/>
            <site name="RL_foot" class="go2foot"/>
          </body>
        </body>
      </body>

      <!-- Right Rear Leg -->
      <body name="RR_hip" pos="-0.1934 -0.0465 0">
        <inertial pos="0.0054 -0.00194 -0.000105" quat="0.499245 0.497014 0.498237 0.505462" mass="0.678"
          diaginertia="0.00088403 0.000596003 0.000479967"/>
        <joint name="RR_hip_joint" class="abduction"/>
        <geom mesh="hip_0" material="metal" class="visual" quat="2.14617e-09 4.63268e-05 4.63268e-05 -1"/>
        <geom mesh="hip_1" material="gray" class="visual" quat="2.14617e-09 4.63268e-05 4.63268e-05 -1"/>
        <!-- Use collision default for right hip (rear) -->
        <geom name="rr_hip" class="hip_right1"/>
        <body name="RR_thigh" pos="0 -0.0955 0">
          <inertial pos="-0.00374 0.0223 -0.0327" quat="0.551623 -0.0200632 0.0847635 0.829533" mass="1.152"
            diaginertia="0.00594973 0.00584149 0.000878787"/>
          <joint name="RR_thigh_joint" class="hip"/>
          <geom mesh="thigh_mirror_0" material="metal" class="visual"/>
          <geom mesh="thigh_mirror_1" material="gray" class="visual"/>
          <!-- Three collision geoms for thigh -->
          <geom name="rr_thigh1" class="thigh1"/>
          <geom name="rr_thigh2" class="thigh2"/>
          <geom name="rr_thigh3" class="thigh3"/>
          <body name="RR_calf" pos="0 0 -0.213">
            <inertial pos="0.00629595 0.000622121 -0.141417" quat="0.703508 -0.00450087 0.00154099 0.710672"
              mass="0.241352" diaginertia="0.0014901 0.00146356 5.31397e-05"/>
            <joint name="RR_calf_joint" class="knee"/>
            <geom mesh="calf_mirror_0" material="gray" class="visual"/>
            <geom mesh="calf_mirror_1" material="black" class="visual"/>
            <!-- Two collision geoms for calf -->
            <geom name="rr_calf1" class="calf1"/>
            <geom name="rr_calf2" class="calf2"/>
            <!-- Foot collision -->
            <geom pos="0 0 -0.213" mesh="foot" class="visual" material="black"/>
            <geom name="RR" class="foot"/>
            <site name="RR_foot" class="go2foot"/>
          </body>
        </body>
      </body>
    </body>
  </worldbody>

  <actuator>
    <general class="abduction" name="FR_hip" joint="FR_hip_joint"/>
    <general class="hip" name="FR_thigh" joint="FR_thigh_joint"/>
    <general class="knee" name="FR_calf" joint="FR_calf_joint"/>
    <general class="abduction" name="FL_hip" joint="FL_hip_joint"/>
    <general class="hip" name="FL_thigh" joint="FL_thigh_joint"/>
    <general class="knee" name="FL_calf" joint="FL_calf_joint"/>
    <general class="abduction" name="RR_hip" joint="RR_hip_joint"/>
    <general class="hip" name="RR_thigh" joint="RR_thigh_joint"/>
    <general class="knee" name="RR_calf" joint="RR_calf_joint"/>
    <general class="abduction" name="RL_hip" joint="RL_hip_joint"/>
    <general class="hip" name="RL_thigh" joint="RL_thigh_joint"/>
    <general class="knee" name="RL_calf" joint="RL_calf_joint"/>
  </actuator>

  <sensor>
    <jointpos joint="FL_hip_joint" name="abduction_front_left_pos"/>
    <jointpos joint="FL_thigh_joint" name="hip_front_left_pos"/>
    <jointpos joint="FL_calf_joint" name="knee_front_left_pos"/>
    <jointpos joint="RL_hip_joint" name="abduction_hind_left_pos"/>
    <jointpos joint="RL_thigh_joint" name="hip_hind_left_pos"/>
    <jointpos joint="RL_calf_joint" name="knee_hind_left_pos"/>
    <jointpos joint="FR_hip_joint" name="abduction_front_right_pos"/>
    <jointpos joint="FR_thigh_joint" name="hip_front_right_pos"/>
    <jointpos joint="FR_calf_joint" name="knee_front_right_pos"/>
    <jointpos joint="RR_hip_joint" name="abduction_hind_right_pos"/>
    <jointpos joint="RR_thigh_joint" name="hip_hind_right_pos"/>
    <jointpos joint="RR_calf_joint" name="knee_hind_right_pos"/>
    <jointvel joint="FL_hip_joint" name="abduction_front_left_vel"/>
    <jointvel joint="FL_thigh_joint" name="hip_front_left_vel"/>
    <jointvel joint="FL_calf_joint" name="knee_front_left_vel"/>
    <jointvel joint="RL_hip_joint" name="abduction_hind_left_vel"/>
    <jointvel joint="RL_thigh_joint" name="hip_hind_left_vel"/>
    <jointvel joint="RL_calf_joint" name="knee_hind_left_vel"/>
    <jointvel joint="FR_hip_joint" name="abduction_front_right_vel"/>
    <jointvel joint="FR_thigh_joint" name="hip_front_right_vel"/>
    <jointvel joint="FR_calf_joint" name="knee_front_right_vel"/>
    <jointvel joint="RR_hip_joint" name="abduction_hind_right_vel"/>
    <jointvel joint="RR_thigh_joint" name="hip_hind_right_vel"/>
    <jointvel joint="RR_calf_joint" name="knee_hind_right_vel"/>
    <gyro site="imu" name="gyro"/>
    <accelerometer site="imu" name="accelerometer"/>
    <framezaxis objtype="site" objname="imu" name="upvector"/>
    <framexaxis objtype="site" objname="imu" name="forwardvector"/>
    <framepos objtype="site" objname="imu" name="position"/>
    <framequat objtype="site" objname="imu" name="orientation"/>
    <framepos objtype="site" objname="imu" name="global_position"/>
    <framelinvel objtype="site" objname="imu" name="global_linvel"/>
    <frameangvel objtype="site" objname="imu" name="global_angvel"/>
    <velocimeter site="imu" name="local_linvel"/>
    <framelinvel objtype="site" objname="FR_foot" name="FR_foot_global_linvel"/>
    <framelinvel objtype="site" objname="FL_foot" name="FL_foot_global_linvel"/>
    <framelinvel objtype="site" objname="RR_foot" name="RR_foot_global_linvel"/>
    <framelinvel objtype="site" objname="RL_foot" name="RL_foot_global_linvel"/>
    <framepos objtype="site" objname="FR_foot" name="FR_foot_pos" reftype="site" refname="imu"/>
    <framepos objtype="site" objname="FL_foot" name="FL_foot_pos" reftype="site" refname="imu"/>
    <framepos objtype="site" objname="RR_foot" name="RR_foot_pos" reftype="site" refname="imu"/>
    <framepos objtype="site" objname="RL_foot" name="RL_foot_pos" reftype="site" refname="imu"/>
    <framepos objtype="site" objname="head" name="head_pos"/>
  </sensor>

</mujoco>
